Traceback (most recent call last):
  File "c:\users\44781\anaconda3\envs\ons-env\lib\site-packages\jupyter_cache\executors\utils.py", line 51, in single_nb_execution
    executenb(
  File "c:\users\44781\anaconda3\envs\ons-env\lib\site-packages\nbclient\client.py", line 1204, in execute
    return NotebookClient(nb=nb, resources=resources, km=km, **kwargs).execute()
  File "c:\users\44781\anaconda3\envs\ons-env\lib\site-packages\nbclient\util.py", line 84, in wrapped
    return just_run(coro(*args, **kwargs))
  File "c:\users\44781\anaconda3\envs\ons-env\lib\site-packages\nbclient\util.py", line 62, in just_run
    return loop.run_until_complete(coro)
  File "C:\Users\44781\anaconda3\lib\asyncio\base_events.py", line 616, in run_until_complete
    return future.result()
  File "c:\users\44781\anaconda3\envs\ons-env\lib\site-packages\nbclient\client.py", line 663, in async_execute
    await self.async_execute_cell(
  File "c:\users\44781\anaconda3\envs\ons-env\lib\site-packages\nbclient\client.py", line 965, in async_execute_cell
    await self._check_raise_for_error(cell, cell_index, exec_reply)
  File "c:\users\44781\anaconda3\envs\ons-env\lib\site-packages\nbclient\client.py", line 862, in _check_raise_for_error
    raise CellExecutionError.from_cell_and_msg(cell, exec_reply_content)
nbclient.exceptions.CellExecutionError: An error occurred while executing the following cell:
------------------
import os
import pandas as pd
import copy
import src.data_loading.loads_from_url as lfu
import src.utils.map_utils as mpu
from src.data_loading.loads_from_url import get_poscode_df

data_file = os.path.join(MAIN_PATH, 'src','utils', 'map_data','combined_data.csv')
df = pd.read_csv(data_file,index_col=0)
df

------------------

[1;31m---------------------------------------------------------------------------[0m
[1;31mImportError[0m                               Traceback (most recent call last)
Cell [1;32mIn[2], line 6[0m
[0;32m      4[0m [38;5;28;01mimport[39;00m [38;5;21;01msrc[39;00m[38;5;21;01m.[39;00m[38;5;21;01mdata_loading[39;00m[38;5;21;01m.[39;00m[38;5;21;01mloads_from_url[39;00m [38;5;28;01mas[39;00m [38;5;21;01mlfu[39;00m
[0;32m      5[0m [38;5;28;01mimport[39;00m [38;5;21;01msrc[39;00m[38;5;21;01m.[39;00m[38;5;21;01mutils[39;00m[38;5;21;01m.[39;00m[38;5;21;01mmap_utils[39;00m [38;5;28;01mas[39;00m [38;5;21;01mmpu[39;00m
[1;32m----> 6[0m [38;5;28;01mfrom[39;00m [38;5;21;01msrc[39;00m[38;5;21;01m.[39;00m[38;5;21;01mdata_loading[39;00m[38;5;21;01m.[39;00m[38;5;21;01mloads_from_url[39;00m [38;5;28;01mimport[39;00m get_poscode_df
[0;32m      8[0m data_file [38;5;241m=[39m os[38;5;241m.[39mpath[38;5;241m.[39mjoin(MAIN_PATH, [38;5;124m'[39m[38;5;124msrc[39m[38;5;124m'[39m,[38;5;124m'[39m[38;5;124mutils[39m[38;5;124m'[39m, [38;5;124m'[39m[38;5;124mmap_data[39m[38;5;124m'[39m,[38;5;124m'[39m[38;5;124mcombined_data.csv[39m[38;5;124m'[39m)
[0;32m      9[0m df [38;5;241m=[39m pd[38;5;241m.[39mread_csv(data_file,index_col[38;5;241m=[39m[38;5;241m0[39m)

[1;31mImportError[0m: cannot import name 'get_poscode_df' from 'src.data_loading.loads_from_url' (C:\Users\44781\Documents\GitHub\Pesticide\src\data_loading\loads_from_url.py)
ImportError: cannot import name 'get_poscode_df' from 'src.data_loading.loads_from_url' (C:\Users\44781\Documents\GitHub\Pesticide\src\data_loading\loads_from_url.py)

