Traceback (most recent call last):
  File "c:\users\44781\anaconda3\envs\ons-env\lib\site-packages\jupyter_cache\executors\utils.py", line 51, in single_nb_execution
    executenb(
  File "c:\users\44781\anaconda3\envs\ons-env\lib\site-packages\nbclient\client.py", line 1204, in execute
    return NotebookClient(nb=nb, resources=resources, km=km, **kwargs).execute()
  File "c:\users\44781\anaconda3\envs\ons-env\lib\site-packages\nbclient\util.py", line 84, in wrapped
    return just_run(coro(*args, **kwargs))
  File "c:\users\44781\anaconda3\envs\ons-env\lib\site-packages\nbclient\util.py", line 62, in just_run
    return loop.run_until_complete(coro)
  File "C:\Users\44781\anaconda3\lib\asyncio\base_events.py", line 616, in run_until_complete
    return future.result()
  File "c:\users\44781\anaconda3\envs\ons-env\lib\site-packages\nbclient\client.py", line 663, in async_execute
    await self.async_execute_cell(
  File "c:\users\44781\anaconda3\envs\ons-env\lib\site-packages\nbclient\client.py", line 965, in async_execute_cell
    await self._check_raise_for_error(cell, cell_index, exec_reply)
  File "c:\users\44781\anaconda3\envs\ons-env\lib\site-packages\nbclient\client.py", line 862, in _check_raise_for_error
    raise CellExecutionError.from_cell_and_msg(cell, exec_reply_content)
nbclient.exceptions.CellExecutionError: An error occurred while executing the following cell:
------------------
map_data_file = os.path.join(MAIN_PATH, "src", "utils", "map_data", "postcode_to_region.csv")
postcodes_df = mpu.get_poscode_df(path_to_csv = map_data_file)
postcodes_df.head()

------------------

[1;31m---------------------------------------------------------------------------[0m
[1;31mAttributeError[0m                            Traceback (most recent call last)
Cell [1;32mIn[3], line 2[0m
[0;32m      1[0m map_data_file [38;5;241m=[39m os[38;5;241m.[39mpath[38;5;241m.[39mjoin(MAIN_PATH, [38;5;124m"[39m[38;5;124msrc[39m[38;5;124m"[39m, [38;5;124m"[39m[38;5;124mutils[39m[38;5;124m"[39m, [38;5;124m"[39m[38;5;124mmap_data[39m[38;5;124m"[39m, [38;5;124m"[39m[38;5;124mpostcode_to_region.csv[39m[38;5;124m"[39m)
[1;32m----> 2[0m postcodes_df [38;5;241m=[39m [43mmpu[49m[38;5;241;43m.[39;49m[43mget_poscode_df[49m(path_to_csv [38;5;241m=[39m map_data_file)
[0;32m      3[0m postcodes_df[38;5;241m.[39mhead()

[1;31mAttributeError[0m: module 'src.utils.map_utils' has no attribute 'get_poscode_df'
AttributeError: module 'src.utils.map_utils' has no attribute 'get_poscode_df'

