Traceback (most recent call last):
  File "c:\users\44781\anaconda3\envs\ons-env\lib\site-packages\jupyter_cache\executors\utils.py", line 51, in single_nb_execution
    executenb(
  File "c:\users\44781\anaconda3\envs\ons-env\lib\site-packages\nbclient\client.py", line 1204, in execute
    return NotebookClient(nb=nb, resources=resources, km=km, **kwargs).execute()
  File "c:\users\44781\anaconda3\envs\ons-env\lib\site-packages\nbclient\util.py", line 84, in wrapped
    return just_run(coro(*args, **kwargs))
  File "c:\users\44781\anaconda3\envs\ons-env\lib\site-packages\nbclient\util.py", line 62, in just_run
    return loop.run_until_complete(coro)
  File "C:\Users\44781\anaconda3\lib\asyncio\base_events.py", line 616, in run_until_complete
    return future.result()
  File "c:\users\44781\anaconda3\envs\ons-env\lib\site-packages\nbclient\client.py", line 663, in async_execute
    await self.async_execute_cell(
  File "c:\users\44781\anaconda3\envs\ons-env\lib\site-packages\nbclient\client.py", line 965, in async_execute_cell
    await self._check_raise_for_error(cell, cell_index, exec_reply)
  File "c:\users\44781\anaconda3\envs\ons-env\lib\site-packages\nbclient\client.py", line 862, in _check_raise_for_error
    raise CellExecutionError.from_cell_and_msg(cell, exec_reply_content)
nbclient.exceptions.CellExecutionError: An error occurred while executing the following cell:
------------------
import pandas as pd
import ezodf
import re
import os

import sys
sys.path.append("..")

import src.data_loading.loads_from_url as lfu
import src.utils.loads_from_url as utils
import src.data_cleaning.modify_dfs as mdf

cwd = os.getcwd()
cwd = re.split(r"[A-Za-z]+$",cwd)[0]

folder_path = os.path.join(cwd, 'data')

file_path = []
for file_ in os.listdir(folder_path):
    if file_.endswith('.ods') and not re.search(r'^_',file_):
        file_path.append(os.path.join(folder_path, file_) )
------------------

[1;31m---------------------------------------------------------------------------[0m
[1;31mModuleNotFoundError[0m                       Traceback (most recent call last)
Cell [1;32mIn[1], line 9[0m
[0;32m      6[0m [38;5;28;01mimport[39;00m [38;5;21;01msys[39;00m
[0;32m      7[0m sys[38;5;241m.[39mpath[38;5;241m.[39mappend([38;5;124m"[39m[38;5;124m..[39m[38;5;124m"[39m)
[1;32m----> 9[0m [38;5;28;01mimport[39;00m [38;5;21;01msrc[39;00m[38;5;21;01m.[39;00m[38;5;21;01mdata_loading[39;00m[38;5;21;01m.[39;00m[38;5;21;01mloads_from_url[39;00m [38;5;28;01mas[39;00m [38;5;21;01mlfu[39;00m
[0;32m     10[0m [38;5;28;01mimport[39;00m [38;5;21;01msrc[39;00m[38;5;21;01m.[39;00m[38;5;21;01mutils[39;00m[38;5;21;01m.[39;00m[38;5;21;01mloads_from_url[39;00m [38;5;28;01mas[39;00m [38;5;21;01mutils[39;00m
[0;32m     11[0m [38;5;28;01mimport[39;00m [38;5;21;01msrc[39;00m[38;5;21;01m.[39;00m[38;5;21;01mdata_cleaning[39;00m[38;5;21;01m.[39;00m[38;5;21;01mmodify_dfs[39;00m [38;5;28;01mas[39;00m [38;5;21;01mmdf[39;00m

[1;31mModuleNotFoundError[0m: No module named 'src'
ModuleNotFoundError: No module named 'src'

