Traceback (most recent call last):
  File "c:\users\44781\anaconda3\envs\ons-env\lib\site-packages\jupyter_cache\executors\utils.py", line 51, in single_nb_execution
    executenb(
  File "c:\users\44781\anaconda3\envs\ons-env\lib\site-packages\nbclient\client.py", line 1204, in execute
    return NotebookClient(nb=nb, resources=resources, km=km, **kwargs).execute()
  File "c:\users\44781\anaconda3\envs\ons-env\lib\site-packages\nbclient\util.py", line 84, in wrapped
    return just_run(coro(*args, **kwargs))
  File "c:\users\44781\anaconda3\envs\ons-env\lib\site-packages\nbclient\util.py", line 62, in just_run
    return loop.run_until_complete(coro)
  File "C:\Users\44781\anaconda3\lib\asyncio\base_events.py", line 616, in run_until_complete
    return future.result()
  File "c:\users\44781\anaconda3\envs\ons-env\lib\site-packages\nbclient\client.py", line 663, in async_execute
    await self.async_execute_cell(
  File "c:\users\44781\anaconda3\envs\ons-env\lib\site-packages\nbclient\client.py", line 965, in async_execute_cell
    await self._check_raise_for_error(cell, cell_index, exec_reply)
  File "c:\users\44781\anaconda3\envs\ons-env\lib\site-packages\nbclient\client.py", line 862, in _check_raise_for_error
    raise CellExecutionError.from_cell_and_msg(cell, exec_reply_content)
nbclient.exceptions.CellExecutionError: An error occurred while executing the following cell:
------------------

cwd = Path(os.getcwd()).parent
cwd =  os.path.join(cwd , "Pesticide")
sys.path.append(cwd)

------------------

[1;31m---------------------------------------------------------------------------[0m
[1;31mNameError[0m                                 Traceback (most recent call last)
Cell [1;32mIn[1], line 1[0m
[1;32m----> 1[0m cwd [38;5;241m=[39m [43mPath[49m(os[38;5;241m.[39mgetcwd())[38;5;241m.[39mparent
[0;32m      2[0m cwd [38;5;241m=[39m  os[38;5;241m.[39mpath[38;5;241m.[39mjoin(cwd , [38;5;124m"[39m[38;5;124mPesticide[39m[38;5;124m"[39m)
[0;32m      3[0m sys[38;5;241m.[39mpath[38;5;241m.[39mappend(cwd)

[1;31mNameError[0m: name 'Path' is not defined
NameError: name 'Path' is not defined

